Watching for file changes with StatReloader
/home/dias/PycharmProjects/study/academy_project/learning/views.py changed, reloading.
Watching for file changes with StatReloader
/home/dias/PycharmProjects/study/academy_project/learning/views.py changed, reloading.
Watching for file changes with StatReloader
/home/dias/PycharmProjects/study/academy_project/learning/views.py changed, reloading.
Watching for file changes with StatReloader
/home/dias/PycharmProjects/study/academy_project/learning/views.py changed, reloading.
Watching for file changes with StatReloader
/home/dias/PycharmProjects/study/academy_project/learning/views.py changed, reloading.
Watching for file changes with StatReloader
/home/dias/PycharmProjects/study/academy_project/learning/views.py changed, reloading.
Watching for file changes with StatReloader
/home/dias/PycharmProjects/study/academy_project/learning/views.py changed, reloading.
Watching for file changes with StatReloader
/home/dias/PycharmProjects/study/academy_project/learning/views.py changed, reloading.
Watching for file changes with StatReloader
Watching for file changes with StatReloader
Watching for file changes with StatReloader
"GET / HTTP/1.1" 200 1176
Попытка входа: username=diasTest
Успешный вход: diasTest
"POST / HTTP/1.1" 302 0
"GET /home/ HTTP/1.1" 200 1196
"GET / HTTP/1.1" 200 1176
Watching for file changes with StatReloader
"GET / HTTP/1.1" 200 1176
Попытка входа: username=dias.shaimerdenov@targetai.kz
Internal Server Error: /
Traceback (most recent call last):
  File "/home/dias/PycharmProjects/study/venv/lib/python3.12/site-packages/django/db/backends/utils.py", line 105, in _execute
    return self.cursor.execute(sql, params)
           ^^^^^^^^^^^^^^^^^^^^^^^^^^^^^^^^
  File "/home/dias/PycharmProjects/study/venv/lib/python3.12/site-packages/django/db/backends/sqlite3/base.py", line 354, in execute
    return super().execute(query, params)
           ^^^^^^^^^^^^^^^^^^^^^^^^^^^^^^
sqlite3.OperationalError: no such table: learning_user

The above exception was the direct cause of the following exception:

Traceback (most recent call last):
  File "/home/dias/PycharmProjects/study/venv/lib/python3.12/site-packages/django/core/handlers/exception.py", line 55, in inner
    response = get_response(request)
               ^^^^^^^^^^^^^^^^^^^^^
  File "/home/dias/PycharmProjects/study/venv/lib/python3.12/site-packages/django/core/handlers/base.py", line 197, in _get_response
    response = wrapped_callback(request, *callback_args, **callback_kwargs)
               ^^^^^^^^^^^^^^^^^^^^^^^^^^^^^^^^^^^^^^^^^^^^^^^^^^^^^^^^^^^^
  File "/home/dias/PycharmProjects/study/academy_project/learning/views.py", line 19, in login_view
    user = User.objects.get(username=username)
           ^^^^^^^^^^^^^^^^^^^^^^^^^^^^^^^^^^^
  File "/home/dias/PycharmProjects/study/venv/lib/python3.12/site-packages/django/db/models/manager.py", line 87, in manager_method
    return getattr(self.get_queryset(), name)(*args, **kwargs)
           ^^^^^^^^^^^^^^^^^^^^^^^^^^^^^^^^^^^^^^^^^^^^^^^^^^^
  File "/home/dias/PycharmProjects/study/venv/lib/python3.12/site-packages/django/db/models/query.py", line 645, in get
    num = len(clone)
          ^^^^^^^^^^
  File "/home/dias/PycharmProjects/study/venv/lib/python3.12/site-packages/django/db/models/query.py", line 382, in __len__
    self._fetch_all()
  File "/home/dias/PycharmProjects/study/venv/lib/python3.12/site-packages/django/db/models/query.py", line 1928, in _fetch_all
    self._result_cache = list(self._iterable_class(self))
                         ^^^^^^^^^^^^^^^^^^^^^^^^^^^^^^^^
  File "/home/dias/PycharmProjects/study/venv/lib/python3.12/site-packages/django/db/models/query.py", line 91, in __iter__
    results = compiler.execute_sql(
              ^^^^^^^^^^^^^^^^^^^^^
  File "/home/dias/PycharmProjects/study/venv/lib/python3.12/site-packages/django/db/models/sql/compiler.py", line 1574, in execute_sql
    cursor.execute(sql, params)
  File "/home/dias/PycharmProjects/study/venv/lib/python3.12/site-packages/django/db/backends/utils.py", line 122, in execute
    return super().execute(sql, params)
           ^^^^^^^^^^^^^^^^^^^^^^^^^^^^
  File "/home/dias/PycharmProjects/study/venv/lib/python3.12/site-packages/django/db/backends/utils.py", line 79, in execute
    return self._execute_with_wrappers(
           ^^^^^^^^^^^^^^^^^^^^^^^^^^^^
  File "/home/dias/PycharmProjects/study/venv/lib/python3.12/site-packages/django/db/backends/utils.py", line 92, in _execute_with_wrappers
    return executor(sql, params, many, context)
           ^^^^^^^^^^^^^^^^^^^^^^^^^^^^^^^^^^^^
  File "/home/dias/PycharmProjects/study/venv/lib/python3.12/site-packages/django/db/backends/utils.py", line 100, in _execute
    with self.db.wrap_database_errors:
         ^^^^^^^^^^^^^^^^^^^^^^^^^^^^
  File "/home/dias/PycharmProjects/study/venv/lib/python3.12/site-packages/django/db/utils.py", line 91, in __exit__
    raise dj_exc_value.with_traceback(traceback) from exc_value
  File "/home/dias/PycharmProjects/study/venv/lib/python3.12/site-packages/django/db/backends/utils.py", line 105, in _execute
    return self.cursor.execute(sql, params)
           ^^^^^^^^^^^^^^^^^^^^^^^^^^^^^^^^
  File "/home/dias/PycharmProjects/study/venv/lib/python3.12/site-packages/django/db/backends/sqlite3/base.py", line 354, in execute
    return super().execute(query, params)
           ^^^^^^^^^^^^^^^^^^^^^^^^^^^^^^
django.db.utils.OperationalError: no such table: learning_user
"POST / HTTP/1.1" 500 141186
Watching for file changes with StatReloader
"GET / HTTP/1.1" 200 1176
Попытка входа: username=dias.shaimerdenov@targetai.kz
Internal Server Error: /
Traceback (most recent call last):
  File "/home/dias/PycharmProjects/study/venv/lib/python3.12/site-packages/django/db/backends/utils.py", line 105, in _execute
    return self.cursor.execute(sql, params)
           ^^^^^^^^^^^^^^^^^^^^^^^^^^^^^^^^
  File "/home/dias/PycharmProjects/study/venv/lib/python3.12/site-packages/django/db/backends/sqlite3/base.py", line 354, in execute
    return super().execute(query, params)
           ^^^^^^^^^^^^^^^^^^^^^^^^^^^^^^
sqlite3.OperationalError: no such table: learning_user

The above exception was the direct cause of the following exception:

Traceback (most recent call last):
  File "/home/dias/PycharmProjects/study/venv/lib/python3.12/site-packages/django/core/handlers/exception.py", line 55, in inner
    response = get_response(request)
               ^^^^^^^^^^^^^^^^^^^^^
  File "/home/dias/PycharmProjects/study/venv/lib/python3.12/site-packages/django/core/handlers/base.py", line 197, in _get_response
    response = wrapped_callback(request, *callback_args, **callback_kwargs)
               ^^^^^^^^^^^^^^^^^^^^^^^^^^^^^^^^^^^^^^^^^^^^^^^^^^^^^^^^^^^^
  File "/home/dias/PycharmProjects/study/academy_project/learning/views.py", line 19, in login_view
    user = User.objects.get(username=username)
           ^^^^^^^^^^^^^^^^^^^^^^^^^^^^^^^^^^^
  File "/home/dias/PycharmProjects/study/venv/lib/python3.12/site-packages/django/db/models/manager.py", line 87, in manager_method
    return getattr(self.get_queryset(), name)(*args, **kwargs)
           ^^^^^^^^^^^^^^^^^^^^^^^^^^^^^^^^^^^^^^^^^^^^^^^^^^^
  File "/home/dias/PycharmProjects/study/venv/lib/python3.12/site-packages/django/db/models/query.py", line 645, in get
    num = len(clone)
          ^^^^^^^^^^
  File "/home/dias/PycharmProjects/study/venv/lib/python3.12/site-packages/django/db/models/query.py", line 382, in __len__
    self._fetch_all()
  File "/home/dias/PycharmProjects/study/venv/lib/python3.12/site-packages/django/db/models/query.py", line 1928, in _fetch_all
    self._result_cache = list(self._iterable_class(self))
                         ^^^^^^^^^^^^^^^^^^^^^^^^^^^^^^^^
  File "/home/dias/PycharmProjects/study/venv/lib/python3.12/site-packages/django/db/models/query.py", line 91, in __iter__
    results = compiler.execute_sql(
              ^^^^^^^^^^^^^^^^^^^^^
  File "/home/dias/PycharmProjects/study/venv/lib/python3.12/site-packages/django/db/models/sql/compiler.py", line 1574, in execute_sql
    cursor.execute(sql, params)
  File "/home/dias/PycharmProjects/study/venv/lib/python3.12/site-packages/django/db/backends/utils.py", line 122, in execute
    return super().execute(sql, params)
           ^^^^^^^^^^^^^^^^^^^^^^^^^^^^
  File "/home/dias/PycharmProjects/study/venv/lib/python3.12/site-packages/django/db/backends/utils.py", line 79, in execute
    return self._execute_with_wrappers(
           ^^^^^^^^^^^^^^^^^^^^^^^^^^^^
  File "/home/dias/PycharmProjects/study/venv/lib/python3.12/site-packages/django/db/backends/utils.py", line 92, in _execute_with_wrappers
    return executor(sql, params, many, context)
           ^^^^^^^^^^^^^^^^^^^^^^^^^^^^^^^^^^^^
  File "/home/dias/PycharmProjects/study/venv/lib/python3.12/site-packages/django/db/backends/utils.py", line 100, in _execute
    with self.db.wrap_database_errors:
         ^^^^^^^^^^^^^^^^^^^^^^^^^^^^
  File "/home/dias/PycharmProjects/study/venv/lib/python3.12/site-packages/django/db/utils.py", line 91, in __exit__
    raise dj_exc_value.with_traceback(traceback) from exc_value
  File "/home/dias/PycharmProjects/study/venv/lib/python3.12/site-packages/django/db/backends/utils.py", line 105, in _execute
    return self.cursor.execute(sql, params)
           ^^^^^^^^^^^^^^^^^^^^^^^^^^^^^^^^
  File "/home/dias/PycharmProjects/study/venv/lib/python3.12/site-packages/django/db/backends/sqlite3/base.py", line 354, in execute
    return super().execute(query, params)
           ^^^^^^^^^^^^^^^^^^^^^^^^^^^^^^
django.db.utils.OperationalError: no such table: learning_user
"POST / HTTP/1.1" 500 141013
