Watching for file changes with StatReloader
/home/dias/PycharmProjects/study/academy_project/learning/views.py changed, reloading.
Watching for file changes with StatReloader
/home/dias/PycharmProjects/study/academy_project/learning/views.py changed, reloading.
Watching for file changes with StatReloader
/home/dias/PycharmProjects/study/academy_project/learning/views.py changed, reloading.
Watching for file changes with StatReloader
/home/dias/PycharmProjects/study/academy_project/learning/views.py changed, reloading.
Watching for file changes with StatReloader
/home/dias/PycharmProjects/study/academy_project/learning/views.py changed, reloading.
Watching for file changes with StatReloader
/home/dias/PycharmProjects/study/academy_project/learning/views.py changed, reloading.
Watching for file changes with StatReloader
/home/dias/PycharmProjects/study/academy_project/learning/views.py changed, reloading.
Watching for file changes with StatReloader
/home/dias/PycharmProjects/study/academy_project/learning/views.py changed, reloading.
Watching for file changes with StatReloader
Watching for file changes with StatReloader
Watching for file changes with StatReloader
"GET / HTTP/1.1" 200 1176
Попытка входа: username=diasTest
Успешный вход: diasTest
"POST / HTTP/1.1" 302 0
"GET /home/ HTTP/1.1" 200 1196
"GET / HTTP/1.1" 200 1176
Watching for file changes with StatReloader
"GET / HTTP/1.1" 200 1176
Not Found: /favicon.ico
"GET /favicon.ico HTTP/1.1" 404 3528
Попытка входа: username=dias.shaimerdenov@targetai.kz
Internal Server Error: /
Traceback (most recent call last):
  File "/home/dias/PycharmProjects/study/venv/lib/python3.11/site-packages/django/core/handlers/exception.py", line 55, in inner
    response = get_response(request)
               ^^^^^^^^^^^^^^^^^^^^^
  File "/home/dias/PycharmProjects/study/venv/lib/python3.11/site-packages/django/core/handlers/base.py", line 197, in _get_response
    response = wrapped_callback(request, *callback_args, **callback_kwargs)
               ^^^^^^^^^^^^^^^^^^^^^^^^^^^^^^^^^^^^^^^^^^^^^^^^^^^^^^^^^^^^
  File "/home/dias/PycharmProjects/study/academy_project/learning/views.py", line 19, in login_view
    user = User.objects.get(username=username)
           ^^^^^^^^^^^^^^^^^^^^^^^^^^^^^^^^^^^
  File "/home/dias/PycharmProjects/study/venv/lib/python3.11/site-packages/django/db/models/manager.py", line 87, in manager_method
    return getattr(self.get_queryset(), name)(*args, **kwargs)
           ^^^^^^^^^^^^^^^^^^^^^^^^^^^^^^^^^^^^^^^^^^^^^^^^^^^
  File "/home/dias/PycharmProjects/study/venv/lib/python3.11/site-packages/django/db/models/query.py", line 633, in get
    raise self.model.DoesNotExist(
learning.models.User.DoesNotExist: User matching query does not exist.
"POST / HTTP/1.1" 500 79137
"GET /admin HTTP/1.1" 301 0
"GET /admin/ HTTP/1.1" 302 0
"GET /admin/login/?next=/admin/ HTTP/1.1" 200 4386
"GET /static/admin/css/base.css HTTP/1.1" 200 22154
"GET /static/admin/css/responsive.css HTTP/1.1" 200 16632
"GET /static/admin/css/nav_sidebar.css HTTP/1.1" 200 2810
"GET /static/admin/css/login.css HTTP/1.1" 200 951
"GET /static/admin/js/theme.js HTTP/1.1" 200 1653
"GET /static/admin/css/dark_mode.css HTTP/1.1" 200 2808
"GET /static/admin/js/nav_sidebar.js HTTP/1.1" 200 3063
"POST /admin/login/?next=/admin/ HTTP/1.1" 200 4684
"POST /admin/login/?next=/admin/ HTTP/1.1" 200 4660
Watching for file changes with StatReloader
"GET / HTTP/1.1" 200 1176
Попытка входа: username=dias.shaymerdenov@bk.ru
Internal Server Error: /
Traceback (most recent call last):
  File "/home/dias/PycharmProjects/study/venv/lib/python3.11/site-packages/django/core/handlers/exception.py", line 55, in inner
    response = get_response(request)
               ^^^^^^^^^^^^^^^^^^^^^
  File "/home/dias/PycharmProjects/study/venv/lib/python3.11/site-packages/django/core/handlers/base.py", line 197, in _get_response
    response = wrapped_callback(request, *callback_args, **callback_kwargs)
               ^^^^^^^^^^^^^^^^^^^^^^^^^^^^^^^^^^^^^^^^^^^^^^^^^^^^^^^^^^^^
  File "/home/dias/PycharmProjects/study/academy_project/learning/views.py", line 19, in login_view
    user = User.objects.get(username=username)
           ^^^^^^^^^^^^^^^^^^^^^^^^^^^^^^^^^^^
  File "/home/dias/PycharmProjects/study/venv/lib/python3.11/site-packages/django/db/models/manager.py", line 87, in manager_method
    return getattr(self.get_queryset(), name)(*args, **kwargs)
           ^^^^^^^^^^^^^^^^^^^^^^^^^^^^^^^^^^^^^^^^^^^^^^^^^^^
  File "/home/dias/PycharmProjects/study/venv/lib/python3.11/site-packages/django/db/models/query.py", line 633, in get
    raise self.model.DoesNotExist(
learning.models.User.DoesNotExist: User matching query does not exist.
"POST / HTTP/1.1" 500 79071
"GET /admin/ HTTP/1.1" 302 0
"GET /admin/login/?next=/admin/ HTTP/1.1" 200 4386
"POST /admin/login/?next=/admin/ HTTP/1.1" 200 4678
"POST /admin/login/?next=/admin/ HTTP/1.1" 200 4678
"POST /admin/login/?next=/admin/ HTTP/1.1" 200 4678
"POST /admin/login/?next=/admin/ HTTP/1.1" 302 0
"GET /admin/ HTTP/1.1" 200 6538
"GET /static/admin/css/dashboard.css HTTP/1.1" 200 441
"GET /static/admin/img/icon-addlink.svg HTTP/1.1" 200 331
"GET /static/admin/img/icon-changelink.svg HTTP/1.1" 200 380
"GET / HTTP/1.1" 200 1176
Попытка входа: username=shaymerdenov.dias@bk.ru
Internal Server Error: /
Traceback (most recent call last):
  File "/home/dias/PycharmProjects/study/venv/lib/python3.11/site-packages/django/core/handlers/exception.py", line 55, in inner
    response = get_response(request)
               ^^^^^^^^^^^^^^^^^^^^^
  File "/home/dias/PycharmProjects/study/venv/lib/python3.11/site-packages/django/core/handlers/base.py", line 197, in _get_response
    response = wrapped_callback(request, *callback_args, **callback_kwargs)
               ^^^^^^^^^^^^^^^^^^^^^^^^^^^^^^^^^^^^^^^^^^^^^^^^^^^^^^^^^^^^
  File "/home/dias/PycharmProjects/study/academy_project/learning/views.py", line 19, in login_view
    user = User.objects.get(username=username)
           ^^^^^^^^^^^^^^^^^^^^^^^^^^^^^^^^^^^
  File "/home/dias/PycharmProjects/study/venv/lib/python3.11/site-packages/django/db/models/manager.py", line 87, in manager_method
    return getattr(self.get_queryset(), name)(*args, **kwargs)
           ^^^^^^^^^^^^^^^^^^^^^^^^^^^^^^^^^^^^^^^^^^^^^^^^^^^
  File "/home/dias/PycharmProjects/study/venv/lib/python3.11/site-packages/django/db/models/query.py", line 633, in get
    raise self.model.DoesNotExist(
learning.models.User.DoesNotExist: User matching query does not exist.
"POST / HTTP/1.1" 500 79230
Watching for file changes with StatReloader
"GET / HTTP/1.1" 200 1176
Попытка входа: username=dias.shaimerdenov@targetai.kz
Internal Server Error: /
Traceback (most recent call last):
  File "/home/dias/PycharmProjects/study/venv/lib/python3.12/site-packages/django/db/backends/utils.py", line 105, in _execute
    return self.cursor.execute(sql, params)
           ^^^^^^^^^^^^^^^^^^^^^^^^^^^^^^^^
  File "/home/dias/PycharmProjects/study/venv/lib/python3.12/site-packages/django/db/backends/sqlite3/base.py", line 354, in execute
    return super().execute(query, params)
           ^^^^^^^^^^^^^^^^^^^^^^^^^^^^^^
sqlite3.OperationalError: no such table: learning_user

The above exception was the direct cause of the following exception:

Traceback (most recent call last):
  File "/home/dias/PycharmProjects/study/venv/lib/python3.12/site-packages/django/core/handlers/exception.py", line 55, in inner
    response = get_response(request)
               ^^^^^^^^^^^^^^^^^^^^^
  File "/home/dias/PycharmProjects/study/venv/lib/python3.12/site-packages/django/core/handlers/base.py", line 197, in _get_response
    response = wrapped_callback(request, *callback_args, **callback_kwargs)
               ^^^^^^^^^^^^^^^^^^^^^^^^^^^^^^^^^^^^^^^^^^^^^^^^^^^^^^^^^^^^
  File "/home/dias/PycharmProjects/study/academy_project/learning/views.py", line 19, in login_view
    user = User.objects.get(username=username)
           ^^^^^^^^^^^^^^^^^^^^^^^^^^^^^^^^^^^
  File "/home/dias/PycharmProjects/study/venv/lib/python3.12/site-packages/django/db/models/manager.py", line 87, in manager_method
    return getattr(self.get_queryset(), name)(*args, **kwargs)
           ^^^^^^^^^^^^^^^^^^^^^^^^^^^^^^^^^^^^^^^^^^^^^^^^^^^
  File "/home/dias/PycharmProjects/study/venv/lib/python3.12/site-packages/django/db/models/query.py", line 645, in get
    num = len(clone)
          ^^^^^^^^^^
  File "/home/dias/PycharmProjects/study/venv/lib/python3.12/site-packages/django/db/models/query.py", line 382, in __len__
    self._fetch_all()
  File "/home/dias/PycharmProjects/study/venv/lib/python3.12/site-packages/django/db/models/query.py", line 1928, in _fetch_all
    self._result_cache = list(self._iterable_class(self))
                         ^^^^^^^^^^^^^^^^^^^^^^^^^^^^^^^^
  File "/home/dias/PycharmProjects/study/venv/lib/python3.12/site-packages/django/db/models/query.py", line 91, in __iter__
    results = compiler.execute_sql(
              ^^^^^^^^^^^^^^^^^^^^^
  File "/home/dias/PycharmProjects/study/venv/lib/python3.12/site-packages/django/db/models/sql/compiler.py", line 1574, in execute_sql
    cursor.execute(sql, params)
  File "/home/dias/PycharmProjects/study/venv/lib/python3.12/site-packages/django/db/backends/utils.py", line 122, in execute
    return super().execute(sql, params)
           ^^^^^^^^^^^^^^^^^^^^^^^^^^^^
  File "/home/dias/PycharmProjects/study/venv/lib/python3.12/site-packages/django/db/backends/utils.py", line 79, in execute
    return self._execute_with_wrappers(
           ^^^^^^^^^^^^^^^^^^^^^^^^^^^^
  File "/home/dias/PycharmProjects/study/venv/lib/python3.12/site-packages/django/db/backends/utils.py", line 92, in _execute_with_wrappers
    return executor(sql, params, many, context)
           ^^^^^^^^^^^^^^^^^^^^^^^^^^^^^^^^^^^^
  File "/home/dias/PycharmProjects/study/venv/lib/python3.12/site-packages/django/db/backends/utils.py", line 100, in _execute
    with self.db.wrap_database_errors:
         ^^^^^^^^^^^^^^^^^^^^^^^^^^^^
  File "/home/dias/PycharmProjects/study/venv/lib/python3.12/site-packages/django/db/utils.py", line 91, in __exit__
    raise dj_exc_value.with_traceback(traceback) from exc_value
  File "/home/dias/PycharmProjects/study/venv/lib/python3.12/site-packages/django/db/backends/utils.py", line 105, in _execute
    return self.cursor.execute(sql, params)
           ^^^^^^^^^^^^^^^^^^^^^^^^^^^^^^^^
  File "/home/dias/PycharmProjects/study/venv/lib/python3.12/site-packages/django/db/backends/sqlite3/base.py", line 354, in execute
    return super().execute(query, params)
           ^^^^^^^^^^^^^^^^^^^^^^^^^^^^^^
django.db.utils.OperationalError: no such table: learning_user
"POST / HTTP/1.1" 500 141186
Watching for file changes with StatReloader
"GET / HTTP/1.1" 200 1176
Попытка входа: username=dias.shaimerdenov@targetai.kz
Internal Server Error: /
Traceback (most recent call last):
  File "/home/dias/PycharmProjects/study/venv/lib/python3.12/site-packages/django/db/backends/utils.py", line 105, in _execute
    return self.cursor.execute(sql, params)
           ^^^^^^^^^^^^^^^^^^^^^^^^^^^^^^^^
  File "/home/dias/PycharmProjects/study/venv/lib/python3.12/site-packages/django/db/backends/sqlite3/base.py", line 354, in execute
    return super().execute(query, params)
           ^^^^^^^^^^^^^^^^^^^^^^^^^^^^^^
sqlite3.OperationalError: no such table: learning_user

The above exception was the direct cause of the following exception:

Traceback (most recent call last):
  File "/home/dias/PycharmProjects/study/venv/lib/python3.12/site-packages/django/core/handlers/exception.py", line 55, in inner
    response = get_response(request)
               ^^^^^^^^^^^^^^^^^^^^^
  File "/home/dias/PycharmProjects/study/venv/lib/python3.12/site-packages/django/core/handlers/base.py", line 197, in _get_response
    response = wrapped_callback(request, *callback_args, **callback_kwargs)
               ^^^^^^^^^^^^^^^^^^^^^^^^^^^^^^^^^^^^^^^^^^^^^^^^^^^^^^^^^^^^
  File "/home/dias/PycharmProjects/study/academy_project/learning/views.py", line 19, in login_view
    user = User.objects.get(username=username)
           ^^^^^^^^^^^^^^^^^^^^^^^^^^^^^^^^^^^
  File "/home/dias/PycharmProjects/study/venv/lib/python3.12/site-packages/django/db/models/manager.py", line 87, in manager_method
    return getattr(self.get_queryset(), name)(*args, **kwargs)
           ^^^^^^^^^^^^^^^^^^^^^^^^^^^^^^^^^^^^^^^^^^^^^^^^^^^
  File "/home/dias/PycharmProjects/study/venv/lib/python3.12/site-packages/django/db/models/query.py", line 645, in get
    num = len(clone)
          ^^^^^^^^^^
  File "/home/dias/PycharmProjects/study/venv/lib/python3.12/site-packages/django/db/models/query.py", line 382, in __len__
    self._fetch_all()
  File "/home/dias/PycharmProjects/study/venv/lib/python3.12/site-packages/django/db/models/query.py", line 1928, in _fetch_all
    self._result_cache = list(self._iterable_class(self))
                         ^^^^^^^^^^^^^^^^^^^^^^^^^^^^^^^^
  File "/home/dias/PycharmProjects/study/venv/lib/python3.12/site-packages/django/db/models/query.py", line 91, in __iter__
    results = compiler.execute_sql(
              ^^^^^^^^^^^^^^^^^^^^^
  File "/home/dias/PycharmProjects/study/venv/lib/python3.12/site-packages/django/db/models/sql/compiler.py", line 1574, in execute_sql
    cursor.execute(sql, params)
  File "/home/dias/PycharmProjects/study/venv/lib/python3.12/site-packages/django/db/backends/utils.py", line 122, in execute
    return super().execute(sql, params)
           ^^^^^^^^^^^^^^^^^^^^^^^^^^^^
  File "/home/dias/PycharmProjects/study/venv/lib/python3.12/site-packages/django/db/backends/utils.py", line 79, in execute
    return self._execute_with_wrappers(
           ^^^^^^^^^^^^^^^^^^^^^^^^^^^^
  File "/home/dias/PycharmProjects/study/venv/lib/python3.12/site-packages/django/db/backends/utils.py", line 92, in _execute_with_wrappers
    return executor(sql, params, many, context)
           ^^^^^^^^^^^^^^^^^^^^^^^^^^^^^^^^^^^^
  File "/home/dias/PycharmProjects/study/venv/lib/python3.12/site-packages/django/db/backends/utils.py", line 100, in _execute
    with self.db.wrap_database_errors:
         ^^^^^^^^^^^^^^^^^^^^^^^^^^^^
  File "/home/dias/PycharmProjects/study/venv/lib/python3.12/site-packages/django/db/utils.py", line 91, in __exit__
    raise dj_exc_value.with_traceback(traceback) from exc_value
  File "/home/dias/PycharmProjects/study/venv/lib/python3.12/site-packages/django/db/backends/utils.py", line 105, in _execute
    return self.cursor.execute(sql, params)
           ^^^^^^^^^^^^^^^^^^^^^^^^^^^^^^^^
  File "/home/dias/PycharmProjects/study/venv/lib/python3.12/site-packages/django/db/backends/sqlite3/base.py", line 354, in execute
    return super().execute(query, params)
           ^^^^^^^^^^^^^^^^^^^^^^^^^^^^^^
django.db.utils.OperationalError: no such table: learning_user
"POST / HTTP/1.1" 500 141013
Watching for file changes with StatReloader
"GET / HTTP/1.1" 200 1176
Попытка входа: username=dias.shaimerdenov@targetai.kz
Internal Server Error: /
Traceback (most recent call last):
  File "/home/dias/PycharmProjects/study/venv/lib/python3.11/site-packages/django/core/handlers/exception.py", line 55, in inner
    response = get_response(request)
               ^^^^^^^^^^^^^^^^^^^^^
  File "/home/dias/PycharmProjects/study/venv/lib/python3.11/site-packages/django/core/handlers/base.py", line 197, in _get_response
    response = wrapped_callback(request, *callback_args, **callback_kwargs)
               ^^^^^^^^^^^^^^^^^^^^^^^^^^^^^^^^^^^^^^^^^^^^^^^^^^^^^^^^^^^^
  File "/home/dias/PycharmProjects/study/academy_project/learning/views.py", line 19, in login_view
    user = User.objects.get(username=username)
           ^^^^^^^^^^^^^^^^^^^^^^^^^^^^^^^^^^^
  File "/home/dias/PycharmProjects/study/venv/lib/python3.11/site-packages/django/db/models/manager.py", line 87, in manager_method
    return getattr(self.get_queryset(), name)(*args, **kwargs)
           ^^^^^^^^^^^^^^^^^^^^^^^^^^^^^^^^^^^^^^^^^^^^^^^^^^^
  File "/home/dias/PycharmProjects/study/venv/lib/python3.11/site-packages/django/db/models/query.py", line 633, in get
    raise self.model.DoesNotExist(
learning.models.User.DoesNotExist: User matching query does not exist.
"POST / HTTP/1.1" 500 79137
Попытка входа: username=shaymerdenov.dias@bk.ru
Internal Server Error: /
Traceback (most recent call last):
  File "/home/dias/PycharmProjects/study/venv/lib/python3.11/site-packages/django/core/handlers/exception.py", line 55, in inner
    response = get_response(request)
               ^^^^^^^^^^^^^^^^^^^^^
  File "/home/dias/PycharmProjects/study/venv/lib/python3.11/site-packages/django/core/handlers/base.py", line 197, in _get_response
    response = wrapped_callback(request, *callback_args, **callback_kwargs)
               ^^^^^^^^^^^^^^^^^^^^^^^^^^^^^^^^^^^^^^^^^^^^^^^^^^^^^^^^^^^^
  File "/home/dias/PycharmProjects/study/academy_project/learning/views.py", line 19, in login_view
    user = User.objects.get(username=username)
           ^^^^^^^^^^^^^^^^^^^^^^^^^^^^^^^^^^^
  File "/home/dias/PycharmProjects/study/venv/lib/python3.11/site-packages/django/db/models/manager.py", line 87, in manager_method
    return getattr(self.get_queryset(), name)(*args, **kwargs)
           ^^^^^^^^^^^^^^^^^^^^^^^^^^^^^^^^^^^^^^^^^^^^^^^^^^^
  File "/home/dias/PycharmProjects/study/venv/lib/python3.11/site-packages/django/db/models/query.py", line 633, in get
    raise self.model.DoesNotExist(
learning.models.User.DoesNotExist: User matching query does not exist.
"POST / HTTP/1.1" 500 79071
Watching for file changes with StatReloader
Попытка входа: username=diasTest
Неверный логин или пароль: diasTest
"POST / HTTP/1.1" 200 1264
Попытка входа: username=diasTest
Неверный логин или пароль: diasTest
"POST / HTTP/1.1" 200 1264
Попытка входа: username=diasTest
Неверный логин или пароль: diasTest
"POST / HTTP/1.1" 200 1264
"GET / HTTP/1.1" 200 1176
/home/dias/PycharmProjects/study/academy_project/learning/urls.py changed, reloading.
Watching for file changes with StatReloader
"GET / HTTP/1.1" 200 1196
"GET /course/1/ HTTP/1.1" 200 1754
/home/dias/PycharmProjects/study/academy_project/learning/forms.py changed, reloading.
Watching for file changes with StatReloader
/home/dias/PycharmProjects/study/academy_project/learning/views.py changed, reloading.
Watching for file changes with StatReloader
/home/dias/PycharmProjects/study/academy_project/learning/views.py changed, reloading.
Watching for file changes with StatReloader
/home/dias/PycharmProjects/study/academy_project/learning/views.py changed, reloading.
Watching for file changes with StatReloader
/home/dias/PycharmProjects/study/academy_project/learning/views.py changed, reloading.
Watching for file changes with StatReloader
/home/dias/PycharmProjects/study/academy_project/learning/views.py changed, reloading.
Watching for file changes with StatReloader
/home/dias/PycharmProjects/study/academy_project/learning/views.py changed, reloading.
Watching for file changes with StatReloader
/home/dias/PycharmProjects/study/academy_project/learning/urls.py changed, reloading.
Watching for file changes with StatReloader
/home/dias/PycharmProjects/study/academy_project/learning/urls.py changed, reloading.
Watching for file changes with StatReloader
/home/dias/PycharmProjects/study/academy_project/learning/urls.py changed, reloading.
Watching for file changes with StatReloader
/home/dias/PycharmProjects/study/academy_project/learning/views.py changed, reloading.
Watching for file changes with StatReloader
"GET /course/1/ HTTP/1.1" 200 1759
"GET /course/1/ HTTP/1.1" 200 1759
"GET /course/1/ HTTP/1.1" 200 1759
"GET /course/1/ HTTP/1.1" 200 1759
"GET /course/1/ HTTP/1.1" 200 1759
Not Found: /
"GET / HTTP/1.1" 404 3221
Not Found: /
"GET / HTTP/1.1" 404 3221
/home/dias/PycharmProjects/study/academy_project/learning/urls.py changed, reloading.
Watching for file changes with StatReloader
/home/dias/PycharmProjects/study/academy_project/learning/views.py changed, reloading.
Watching for file changes with StatReloader
"GET / HTTP/1.1" 200 1212
Internal Server Error: /
Traceback (most recent call last):
  File "/home/dias/PycharmProjects/study/venv/lib/python3.11/site-packages/django/core/handlers/exception.py", line 55, in inner
    response = get_response(request)
               ^^^^^^^^^^^^^^^^^^^^^
  File "/home/dias/PycharmProjects/study/venv/lib/python3.11/site-packages/django/core/handlers/base.py", line 197, in _get_response
    response = wrapped_callback(request, *callback_args, **callback_kwargs)
               ^^^^^^^^^^^^^^^^^^^^^^^^^^^^^^^^^^^^^^^^^^^^^^^^^^^^^^^^^^^^
  File "/home/dias/PycharmProjects/study/venv/lib/python3.11/site-packages/django/views/generic/base.py", line 104, in view
    return self.dispatch(request, *args, **kwargs)
           ^^^^^^^^^^^^^^^^^^^^^^^^^^^^^^^^^^^^^^^
  File "/home/dias/PycharmProjects/study/venv/lib/python3.11/site-packages/django/views/generic/base.py", line 143, in dispatch
    return handler(request, *args, **kwargs)
           ^^^^^^^^^^^^^^^^^^^^^^^^^^^^^^^^^
  File "/home/dias/PycharmProjects/study/venv/lib/python3.11/site-packages/django/views/generic/edit.py", line 151, in post
    return self.form_valid(form)
           ^^^^^^^^^^^^^^^^^^^^^
  File "/home/dias/PycharmProjects/study/academy_project/learning/views.py", line 19, in form_valid
    return super().form_valid(form)
           ^^^^^^^^^^^^^^^^^^^^^^^^
  File "/home/dias/PycharmProjects/study/venv/lib/python3.11/site-packages/django/views/generic/edit.py", line 63, in form_valid
    return HttpResponseRedirect(self.get_success_url())
                                ^^^^^^^^^^^^^^^^^^^^^^
  File "/home/dias/PycharmProjects/study/venv/lib/python3.11/site-packages/django/views/generic/edit.py", line 57, in get_success_url
    if not self.success_url:
  File "/home/dias/PycharmProjects/study/venv/lib/python3.11/site-packages/django/utils/functional.py", line 187, in __wrapper__
    result = func(*self._args, **self._kw)
             ^^^^^^^^^^^^^^^^^^^^^^^^^^^^^
  File "/home/dias/PycharmProjects/study/venv/lib/python3.11/site-packages/django/urls/base.py", line 98, in reverse
    resolved_url = resolver._reverse_with_prefix(view, prefix, *args, **kwargs)
                   ^^^^^^^^^^^^^^^^^^^^^^^^^^^^^^^^^^^^^^^^^^^^^^^^^^^^^^^^^^^^
  File "/home/dias/PycharmProjects/study/venv/lib/python3.11/site-packages/django/urls/resolvers.py", line 831, in _reverse_with_prefix
    raise NoReverseMatch(msg)
django.urls.exceptions.NoReverseMatch: Reverse for 'home' not found. 'home' is not a valid view function or pattern name.
"POST / HTTP/1.1" 500 108561
/home/dias/PycharmProjects/study/academy_project/learning/views.py changed, reloading.
Watching for file changes with StatReloader
"POST / HTTP/1.1" 302 0
"GET /home/ HTTP/1.1" 200 1196
"GET / HTTP/1.1" 200 1212
"POST / HTTP/1.1" 302 0
"GET /home/ HTTP/1.1" 200 1196
"GET /course/1/ HTTP/1.1" 200 1759
/home/dias/PycharmProjects/study/academy_project/learning/views.py changed, reloading.
Watching for file changes with StatReloader
"GET /course/2/ HTTP/1.1" 200 1754
"GET /home/ HTTP/1.1" 200 1196
"GET /course/2/ HTTP/1.1" 200 1754
"GET /home/ HTTP/1.1" 200 1196
"GET / HTTP/1.1" 200 1212
/home/dias/PycharmProjects/study/academy_project/learning/views.py changed, reloading.
Watching for file changes with StatReloader
"POST / HTTP/1.1" 302 0
"GET /home/ HTTP/1.1" 200 1196
/home/dias/PycharmProjects/study/academy_project/learning/views.py changed, reloading.
Watching for file changes with StatReloader
"GET / HTTP/1.1" 200 1212
/home/dias/PycharmProjects/study/academy_project/learning/views.py changed, reloading.
Watching for file changes with StatReloader
/home/dias/PycharmProjects/study/academy_project/learning/views.py changed, reloading.
Watching for file changes with StatReloader
/home/dias/PycharmProjects/study/academy_project/learning/views.py changed, reloading.
Watching for file changes with StatReloader
"GET / HTTP/1.1" 200 1212
"GET / HTTP/1.1" 200 1212
"POST / HTTP/1.1" 302 0
"GET /home/ HTTP/1.1" 200 1196
/home/dias/PycharmProjects/study/academy_project/learning/views.py changed, reloading.
Watching for file changes with StatReloader
/home/dias/PycharmProjects/study/academy_project/learning/urls.py changed, reloading.
Watching for file changes with StatReloader
/home/dias/PycharmProjects/study/academy_project/learning/urls.py changed, reloading.
Watching for file changes with StatReloader
/home/dias/PycharmProjects/study/academy_project/learning/urls.py changed, reloading.
Watching for file changes with StatReloader
"GET /home/ HTTP/1.1" 200 1196
"GET / HTTP/1.1" 200 1212
"POST / HTTP/1.1" 302 0
"GET /redirect/ HTTP/1.1" 302 0
"GET /home/ HTTP/1.1" 200 1196
/home/dias/PycharmProjects/study/academy_project/learning/views.py changed, reloading.
Watching for file changes with StatReloader
"GET /course/1/ HTTP/1.1" 200 1759
"POST /enroll/ HTTP/1.1" 200 2022
